<?xml version="1.0"?>
<robot name="my_robot" xmlns:xacro="http://www.ros.org/wiki/xacro">
<xacro:include filename="$(find my_rb1_description)/urdf/robot.gazebo"/>
<material name="blue">
<color rgba="0 0 1 1"/>
</material>
<material name="red">
<color rgba="1 0 0 1"/>
</material>
<material name="grey">
<color rgba="0.5 0.5 0.5 1"/>
</material>

<!--  Define Properties -->
<xacro:property name="wheel_radius" value="0.025"/> <!-- 2.5 cm -->
<xacro:property name="wheel_length" value="0.02"/> <!-- 2 cm -->
<xacro:property name="wheel_mass" value="4"/> <!-- Mass of one wheel -->
<xacro:property name="caster_mass" value="1"/> <!-- Mass of one caster wheel -->
<xacro:property name="base_mass" value="14"/> <!-- Mass of base -->
<xacro:property name="lidar_mass" value="0.5"/> <!-- Mass of LIDAR -->

<!--  Wheel Macro -->
<xacro:macro name="wheel_link" params="prefix x y z r p yaw">
    <link name="${prefix}_wheel_link">
        <inertial>
            <mass value="${wheel_mass}"/>
            <origin xyz="${x} ${y} ${z}" rpy="${r} ${p} ${yaw}"/>
            <inertia ixx="${1/12 * wheel_mass * (3 * wheel_radius * wheel_radius + wheel_length * wheel_length)}" 
                     ixy="0" 
                     ixz="0" 
                     iyy="${1/12 * wheel_mass * (3 * wheel_radius * wheel_radius + wheel_length * wheel_length)}" 
                     iyz="0" 
                     izz="${1/2 * wheel_mass * wheel_radius * wheel_radius}"/>
        </inertial>
        <collision>
            <geometry>
                <cylinder radius="${wheel_radius}" length="${wheel_length}"/>
            </geometry>
            <origin xyz="${x} ${y} ${z}" rpy="${r} ${p} ${yaw}"/>
        </collision>
        <visual>
            <geometry>
                <cylinder radius="${wheel_radius}" length="${wheel_length}"/>
            </geometry>
            <origin xyz="${x} ${y} ${z}" rpy="${r} ${p} ${yaw}"/>
            <material name="red"/>
        </visual>
    </link>
</xacro:macro>

<!--  Wheel Joint Macro -->
<xacro:macro name="wheel_joint" params="prefix x y z r p yaw">
    <joint name="${prefix}_wheel_joint" type="continuous">
        <parent link="base_link"/>
        <child link="${prefix}_wheel_link"/>
        <origin xyz="${x} ${y} ${z-0.125}" rpy="${r} ${p} ${yaw}"/>
        <axis xyz="0 0 1"/>  <!-- Ensure wheels rotate along the correct axis -->
    </joint>
</xacro:macro>
<!--base_foot_link and jin-->
<link name="base_footprint">
<origin xyz="0 0 0"/>

</link>
<joint name="base_foot_joint" type="fixed">
<parent link ="base_footprint"/>
<child link ="base_link"/>
<origin xyz="0 0 0.125" rpy="0 0 0"/>
</joint>
<!-- Base Link -->
<link name="base_link">
    <inertial>
        <mass value="${base_mass}"/>
        <origin xyz="0 0 0" rpy="0 0 0"/>
        <inertia ixx="0.5" ixy="0" ixz="0" 
                 iyy="0.5" iyz="0" 
                 izz="0.5"/> <!-- Approximate values -->
    </inertial>
    <collision>
        <geometry>
            <cylinder length="0.3" radius="0.25"/>
        </geometry>
        <origin xyz="0 0 0" rpy="0 0 0"/>
    </collision>
    <visual>
        <geometry>
            <cylinder length="0.3" radius="0.25"/>
        </geometry>
        <origin xyz="0 0 0" rpy="0 0 0"/>
        <material name="blue"/>
    </visual>
</link>

<!--  Wheels -->
<xacro:wheel_link prefix="base_left" x="0" y="0" z="0" r="0" p="0" yaw="0"/>
<xacro:wheel_link prefix="base_right" x="0" y="0" z="0" r="0" p="0" yaw="0"/>

<!--  Wheel Joints -->
<xacro:wheel_joint prefix="base_left" x="0" y="-0.2" z="-0.015" r="-1.57" p="0" yaw="0"/>
<xacro:wheel_joint prefix="base_right" x="0" y="0.2" z="-0.015" r="-1.57" p="0" yaw="0"/>




<!-- Front Caster -->
<link name="caster_front_wheel_link">
    <inertial>
        <mass value="${caster_mass}"/>
        <origin xyz="0 0 0" rpy="0 0 0"/>
        <inertia ixx="0.01" ixy="0" ixz="0" 
                 iyy="0.01" iyz="0" 
                 izz="0.01"/> <!-- Approximate values -->
    </inertial>
    <visual>
        <geometry>
            <sphere radius="0.025"/>
        </geometry>
        <origin xyz="0 0 -0.125" rpy="0 0 0"/>
        <material name="grey"/>
    </visual>
    <collision>
        <geometry>
            <sphere radius="0.025"/>
        </geometry>
        <origin xyz="0 0 -0.125" rpy="0 0 0"/>
    </collision>
</link>

<!-- Front Caster Joint -->
<joint name="caster_front_joint" type="fixed">
    <parent link="base_link"/>
    <child link="caster_front_wheel_link"/>
    <origin xyz="0.1 0 -0.015" rpy="0 0 0"/>
</joint>

<!-- Rear Caster -->
<link name="caster_rear_wheel_link">
    <inertial>
        <mass value="${caster_mass}"/>
        <origin xyz="0 0 0" rpy="0 0 0"/>
        <inertia ixx="0.01" ixy="0" ixz="0" 
                 iyy="0.01" iyz="0" 
                 izz="0.01"/> <!-- Approximate values -->
    </inertial>
    <visual>
        <geometry>
            <sphere radius="0.025"/>
        </geometry>
        <origin xyz="0 0 -0.125" rpy="0 0 0"/>
        <material name="grey"/>
    </visual>
    <collision>
        <geometry>
            <sphere radius="0.025"/>
        </geometry>
        <origin xyz="0 0 -0.125" rpy="0 0 0"/>
    </collision>
</link>

<!--  Rear Caster Joint -->
<joint name="caster_rear_joint" type="fixed">
    <parent link="base_link"/>
    <child link="caster_rear_wheel_link"/>
    <origin xyz="-0.1 0 -0.015" rpy="0 0 0"/>
</joint>

<!--  LIDAR Sensor -->
<link name="link_laser_scan">
    <inertial>
        <mass value="${lidar_mass}"/>
        <origin xyz="0 0 0" rpy="0 0 0"/>
        <inertia ixx="0.005" ixy="0" ixz="0" 
                 iyy="0.005" iyz="0" 
                 izz="0.005"/> <!-- Approximate values -->
    </inertial>
    <collision>
        <geometry>
            <cylinder radius="0.03" length="0.05"/>
                        <origin xyz="0 0 0" rpy="3.1457 0 0"/>

        </geometry>
    </collision>
    <visual>
        <geometry>
            <cylinder radius="0.03" length="0.05"/>
        </geometry>
            <origin xyz="0 0 0" rpy="3.1457 0 0"/>

        <material name="grey"/>
    </visual>
</link>

<!--  LIDAR Joint -->
<joint name="joint_laser_scan_chassis" type="fixed">
    <origin xyz="0.25 0 0.075" rpy="3.1457 0 0"/>
    <child link="link_laser_scan"/>
    <parent link="base_link"/>
</joint>

</robot>